<?xml version="1.0" encoding="utf-8"?>
<!-- =================================================================================== -->
<!-- |    This document was autogenerated by xacro from ur5e_gripper.xacro             | -->
<!-- |    EDITING THIS FILE BY HAND IS NOT RECOMMENDED                                 | -->
<!-- =================================================================================== -->
<robot name="o2ac_base_scene">
  <!-- measured from model -->
  <!-- link lengths used in model -->
  <!-- manually measured -->
  <link name="a_bot_base_link">
    <visual>
      <origin rpy="0 0 3.14159265359" xyz="0 0 0"/>
      <geometry>
        <mesh filename="package://ur_e_description/meshes/ur5e/visual/base.dae"/>
      </geometry>
      <material name="LightGrey">
        <color rgba="0.7 0.7 0.7 1.0"/>
      </material>
    </visual>
    <collision>
      <origin rpy="0 0 3.14159265359" xyz="0 0 0"/>
      <geometry>
        <mesh filename="package://ur_e_description/meshes/ur5e/collision/base.stl"/>
      </geometry>
    </collision>
    <inertial>
      <mass value="4.0"/>
      <origin rpy="0 0 0" xyz="0.0 0.0 0.0"/>
      <inertia ixx="0.00443333156" ixy="0.0" ixz="0.0" iyy="0.00443333156" iyz="0.0" izz="0.0072"/>
    </inertial>
  </link>
  <joint name="a_bot_shoulder_pan_joint" type="revolute">
    <parent link="a_bot_base_link"/>
    <child link="a_bot_shoulder_link"/>
    <origin rpy="0 0 3.14159265094" xyz="0 0 0.162655931584"/>
    <axis xyz="0 0 1"/>
    <limit effort="150.0" lower="-3.14159265359" upper="3.14159265359" velocity="3.14"/>
    <dynamics damping="0.0" friction="0.0"/>
  </joint>
  <link name="a_bot_shoulder_link">
    <visual>
      <origin rpy="0 0 3.14159265359" xyz="0 0 0"/>
      <geometry>
        <mesh filename="package://ur_e_description/meshes/ur5e/visual/shoulder.dae"/>
      </geometry>
      <material name="LightGrey">
        <color rgba="0.7 0.7 0.7 1.0"/>
      </material>
    </visual>
    <collision>
      <origin rpy="0 0 3.14159265359" xyz="0 0 0"/>
      <geometry>
        <mesh filename="package://ur_e_description/meshes/ur5e/collision/shoulder.stl"/>
      </geometry>
    </collision>
    <inertial>
      <mass value="3.7"/>
      <origin rpy="0 0 0" xyz="0.0 0.0 0.0"/>
      <inertia ixx="0.010267495893" ixy="0.0" ixz="0.0" iyy="0.010267495893" iyz="0.0" izz="0.00666"/>
    </inertial>
  </link>
  <joint name="a_bot_shoulder_lift_joint" type="revolute">
    <parent link="a_bot_shoulder_link"/>
    <child link="a_bot_upper_arm_link"/>
    <origin rpy="1.56953512795 0 -2.84084164664e-07" xyz="0.000134779578882 0 0"/>
    <axis xyz="0 0 1"/>
    <limit effort="150.0" lower="-3.14159265359" upper="3.14159265359" velocity="3.14"/>
    <dynamics damping="0.0" friction="0.0"/>
  </joint>
  <link name="a_bot_upper_arm_link">
    <visual>
      <origin rpy="1.57079632679 0 -1.57079632679" xyz="0 0 0.138"/>
      <geometry>
        <mesh filename="package://ur_e_description/meshes/ur5e/visual/upperarm.dae"/>
      </geometry>
      <material name="LightGrey">
        <color rgba="0.7 0.7 0.7 1.0"/>
      </material>
    </visual>
    <collision>
      <origin rpy="1.57079632679 0 -1.57079632679" xyz="0 0 0.138"/>
      <geometry>
        <mesh filename="package://ur_e_description/meshes/ur5e/collision/upperarm.stl"/>
      </geometry>
    </collision>
    <inertial>
      <mass value="8.393"/>
      <origin rpy="0 1.57079632679 0" xyz="-0.212633383271 0.0 0.138"/>
      <inertia ixx="0.138293379943" ixy="0.0" ixz="0.0" iyy="0.138293379943" iyz="0.0" izz="0.0236053125"/>
    </inertial>
  </link>
  <joint name="a_bot_elbow_joint" type="revolute">
    <parent link="a_bot_upper_arm_link"/>
    <child link="a_bot_forearm_link"/>
    <origin rpy="0.000119395911412 0.00163456023303 5.12790813273e-07" xyz="-0.425266766542 0 0"/>
    <axis xyz="0 0 1"/>
    <limit effort="150.0" lower="0.0" upper="3.14159265359" velocity="3.14"/>
    <dynamics damping="0.0" friction="0.0"/>
  </joint>
  <link name="a_bot_forearm_link">
    <visual>
      <origin rpy="1.57079632679 0 -1.57079632679" xyz="0 0 0.007"/>
      <geometry>
        <mesh filename="package://ur_e_description/meshes/ur5e/visual/forearm.dae"/>
      </geometry>
      <material name="LightGrey">
        <color rgba="0.7 0.7 0.7 1.0"/>
      </material>
    </visual>
    <collision>
      <origin rpy="1.57079632679 0 -1.57079632679" xyz="0 0 0.007"/>
      <geometry>
        <mesh filename="package://ur_e_description/meshes/ur5e/collision/forearm.stl"/>
      </geometry>
    </collision>
    <inertial>
      <mass value="2.275"/>
      <origin rpy="0 1.57079632679 0" xyz="-0.212633383271 0.0 0.007"/>
      <inertia ixx="0.0324280715332" ixy="0.0" ixz="0.0" iyy="0.0324280715332" iyz="0.0" izz="0.0063984375"/>
    </inertial>
  </link>
  <joint name="a_bot_wrist_1_joint" type="revolute">
    <parent link="a_bot_forearm_link"/>
    <child link="a_bot_wrist_1_link"/>
    <origin rpy="0.00240514304011 -0.00147917631702 -3.8502770334e-07" xyz="-0.392650273076 -0.000321358811681 0.133612923084"/>
    <axis xyz="0 0 1"/>
    <limit effort="28.0" lower="-4.71238898038" upper="3.14159265359" velocity="6.28"/>
    <dynamics damping="0.0" friction="0.0"/>
  </joint>
  <link name="a_bot_wrist_1_link">
    <visual>
      <origin rpy="1.57079632679 0 0" xyz="0 0 -0.127"/>
      <geometry>
        <mesh filename="package://ur_e_description/meshes/ur5e/visual/wrist1.dae"/>
      </geometry>
      <material name="LightGrey">
        <color rgba="0.7 0.7 0.7 1.0"/>
      </material>
    </visual>
    <collision>
      <origin rpy="1.57079632679 0 0" xyz="0 0 -0.127"/>
      <geometry>
        <mesh filename="package://ur_e_description/meshes/ur5e/collision/wrist1.stl"/>
      </geometry>
    </collision>
    <inertial>
      <mass value="1.219"/>
      <origin rpy="0 0 0" xyz="0.0 0.0 0.0"/>
      <inertia ixx="0.00272444225937" ixy="0.0" ixz="0.0" iyy="0.00272444225937" iyz="0.0" izz="0.0034284375"/>
    </inertial>
  </link>
  <joint name="a_bot_wrist_2_joint" type="revolute">
    <parent link="a_bot_wrist_1_link"/>
    <child link="a_bot_wrist_2_link"/>
    <origin rpy="1.56963272494 0 9.63633041889e-08" xyz="8.31335451575e-05 -0.0997235522137 0.000116038562953"/>
    <axis xyz="0 0 1"/>
    <limit effort="28.0" lower="-4.71238898038" upper="4.71238898038" velocity="6.28"/>
    <dynamics damping="0.0" friction="0.0"/>
  </joint>
  <link name="a_bot_wrist_2_link">
    <visual>
      <origin rpy="0 0 0" xyz="0 0 -0.0997"/>
      <geometry>
        <mesh filename="package://ur_e_description/meshes/ur5e/visual/wrist2.dae"/>
      </geometry>
      <material name="LightGrey">
        <color rgba="0.7 0.7 0.7 1.0"/>
      </material>
    </visual>
    <collision>
      <origin rpy="0 0 0" xyz="0 0 -0.0997"/>
      <geometry>
        <mesh filename="package://ur_e_description/meshes/ur5e/collision/wrist2.stl"/>
      </geometry>
    </collision>
    <inertial>
      <mass value="1.219"/>
      <origin rpy="0 0 0" xyz="0.0 0.0 0.0"/>
      <inertia ixx="0.00272116872319" ixy="0.0" ixz="0.0" iyy="0.00272116872319" iyz="0.0" izz="0.0034284375"/>
    </inertial>
  </link>
  <joint name="a_bot_wrist_3_joint" type="revolute">
    <parent link="a_bot_wrist_2_link"/>
    <child link="a_bot_wrist_3_link"/>
    <origin rpy="1.57226982462 3.14159265359 3.14159261802" xyz="8.83928394576e-05 0.0995618487303 0.000146704273679"/>
    <axis xyz="0 0 1"/>
    <limit effort="28.0" lower="-6.28318530718" upper="6.28318530718" velocity="6.28"/>
    <dynamics damping="0.0" friction="0.0"/>
  </joint>
  <link name="a_bot_wrist_3_link">
    <visual>
      <origin rpy="1.57079632679 0 0" xyz="0 0 -0.0989"/>
      <geometry>
        <mesh filename="package://ur_e_description/meshes/ur5e/visual/wrist3.dae"/>
      </geometry>
      <material name="LightGrey">
        <color rgba="0.7 0.7 0.7 1.0"/>
      </material>
    </visual>
    <collision>
      <origin rpy="1.57079632679 0 0" xyz="0 0 -0.0989"/>
      <geometry>
        <mesh filename="package://ur_e_description/meshes/ur5e/collision/wrist3.stl"/>
      </geometry>
    </collision>
    <inertial>
      <mass value="0.1879"/>
      <origin rpy="0 0 0" xyz="0.0 0.0 -0.025"/>
      <inertia ixx="0.000134270154625" ixy="0.0" ixz="0.0" iyy="0.000134270154625" iyz="0.0" izz="0.00019024875"/>
    </inertial>
  </link>
  <joint name="a_bot_ee_fixed_joint" type="fixed">
    <parent link="a_bot_wrist_3_link"/>
    <child link="a_bot_ee_link"/>
    <origin rpy="0.0 -1.57079632679 1.57079632679" xyz="0.0 0.0 0.0"/>
  </joint>
  <link name="a_bot_ee_link">
    <collision>
      <geometry>
        <box size="0.01 0.01 0.01"/>
      </geometry>
      <origin rpy="0 0 0" xyz="-0.01 0 0"/>
    </collision>
  </link>
  <transmission name="a_bot_shoulder_pan_trans">
    <type>transmission_interface/SimpleTransmission</type>
    <joint name="a_bot_shoulder_pan_joint">
      <hardwareInterface>hardware_interface/PositionJointInterface</hardwareInterface>
    </joint>
    <actuator name="a_bot_shoulder_pan_motor">
      <mechanicalReduction>1</mechanicalReduction>
    </actuator>
  </transmission>
  <transmission name="a_bot_shoulder_lift_trans">
    <type>transmission_interface/SimpleTransmission</type>
    <joint name="a_bot_shoulder_lift_joint">
      <hardwareInterface>hardware_interface/PositionJointInterface</hardwareInterface>
    </joint>
    <actuator name="a_bot_shoulder_lift_motor">
      <mechanicalReduction>1</mechanicalReduction>
    </actuator>
  </transmission>
  <transmission name="a_bot_elbow_trans">
    <type>transmission_interface/SimpleTransmission</type>
    <joint name="a_bot_elbow_joint">
      <hardwareInterface>hardware_interface/PositionJointInterface</hardwareInterface>
    </joint>
    <actuator name="a_bot_elbow_motor">
      <mechanicalReduction>1</mechanicalReduction>
    </actuator>
  </transmission>
  <transmission name="a_bot_wrist_1_trans">
    <type>transmission_interface/SimpleTransmission</type>
    <joint name="a_bot_wrist_1_joint">
      <hardwareInterface>hardware_interface/PositionJointInterface</hardwareInterface>
    </joint>
    <actuator name="a_bot_wrist_1_motor">
      <mechanicalReduction>1</mechanicalReduction>
    </actuator>
  </transmission>
  <transmission name="a_bot_wrist_2_trans">
    <type>transmission_interface/SimpleTransmission</type>
    <joint name="a_bot_wrist_2_joint">
      <hardwareInterface>hardware_interface/PositionJointInterface</hardwareInterface>
    </joint>
    <actuator name="a_bot_wrist_2_motor">
      <mechanicalReduction>1</mechanicalReduction>
    </actuator>
  </transmission>
  <transmission name="a_bot_wrist_3_trans">
    <type>transmission_interface/SimpleTransmission</type>
    <joint name="a_bot_wrist_3_joint">
      <hardwareInterface>hardware_interface/PositionJointInterface</hardwareInterface>
    </joint>
    <actuator name="a_bot_wrist_3_motor">
      <mechanicalReduction>1</mechanicalReduction>
    </actuator>
  </transmission>
  <gazebo reference="a_bot_shoulder_link">
    <selfCollide>true</selfCollide>
  </gazebo>
  <gazebo reference="a_bot_upper_arm_link">
    <selfCollide>true</selfCollide>
  </gazebo>
  <gazebo reference="a_bot_forearm_link">
    <selfCollide>true</selfCollide>
  </gazebo>
  <gazebo reference="a_bot_wrist_1_link">
    <selfCollide>true</selfCollide>
  </gazebo>
  <gazebo reference="a_bot_wrist_3_link">
    <selfCollide>true</selfCollide>
  </gazebo>
  <gazebo reference="a_bot_wrist_2_link">
    <selfCollide>true</selfCollide>
  </gazebo>
  <gazebo reference="a_bot_ee_link">
    <selfCollide>true</selfCollide>
  </gazebo>
  <!-- ROS base_link to UR 'Base' Coordinates transform -->
  <link name="a_bot_base"/>
  <joint name="a_bot_base_link-base_fixed_joint" type="fixed">
    <!-- NOTE: this rotation is only needed as long as base_link itself is
                 not corrected wrt the real robot (ie: rotated over 180
                 degrees)
      -->
    <origin rpy="0 0 -3.14159265359" xyz="0 0 0"/>
    <parent link="a_bot_base_link"/>
    <child link="a_bot_base"/>
  </joint>
  <!-- Frame coincident with all-zeros TCP on UR controller -->
  <link name="a_bot_tool0"/>
  <joint name="a_bot_wrist_3_link-tool0_fixed_joint" type="fixed">
    <origin rpy="0 0 0" xyz="0 0 0"/>
    <parent link="a_bot_wrist_3_link"/>
    <child link="a_bot_tool0"/>
  </joint>
  <joint name="world_a_bot_joint" type="fixed">
    <parent link="world"/>
    <child link="a_bot_base_link"/>
    <!-- <origin rpy="0.0 0.0 0.0" xyz="-0.004 -0.525 0.75"/> -->
    <origin rpy="0.0 0.0 0.0" xyz="0 0 0"/>
  </joint>
  <link name="world"/>
</robot>

